<?xml version='1.0'?>
<sdf version='1.6'>

<model name="velodyne_hdl-32">
  <link name="base">
    <pose>0 0 0.029335 0 0 0</pose>
    <inertial>
        <mass>1.2</mass>
        <inertia>
            <ixx>0.000890435</ixx>
            <iyy>0.000890435</iyy>
            <izz>0.001092437</izz>
            <ixy>0</ixy>
            <ixz>0</ixz>
            <iyz>0</iyz>
        </inertia>
    </inertial>
    <collision name="base_collision">
      <geometry>
        <cylinder>
          <radius>.04267</radius>
          <length>.05867</length>
        </cylinder>
      </geometry>
    </collision>
    <visual name="base_visual">
      <pose>0 0 -0.029335 0 0 0</pose>
      <geometry>
        <mesh>
            <uri>model://velodyne_hdl-32/meshes/base_t.dae</uri>
        </mesh>
        <!-- 
        <cylinder>
          <radius>.04267</radius>
          <length>.05867</length>
        </cylinder>
        -->
      </geometry>
    </visual>
  </link>

  <link name="top">
    <pose>0 0 0.095455 0 0 0</pose>
    <inertial>
        <mass>0.1</mass>
        <inertia>
            <ixx>0.000090623</ixx>
            <iyy>0.000090623</iyy>
            <izz>0.000091045</izz>
            <ixy>0</ixy>
            <ixz>0</ixz>
            <iyz>0</iyz>
        </inertia>
    </inertial>
    <sensor type="ray" name="sensor">
      <pose>0 0 -0.004645 1.5707 0 0</pose>
      <visualize>1</visualize>
      <!-- 生成传感器数据的频率 -->
      <update_rate>30</update_rate>
      <ray>
          <scan>
            <horizontal>
              <samples>32</samples>
              <resolution>1</resolution>
              <min_angle>-0.53529248</min_angle>
              <max_angle>0.18622663</max_angle>
            </horizontal>
          </scan>
          <range>
            <min>0.05</min>
            <max>70</max>
            <resolution>0.02</resolution>
          </range>
          <noise>
              <!-- 目前支持配置 -->
              <type>gaussian</type>
              <!-- 均值 -->
              <mean>0.0</mean>
              <!-- 标准差 -->
              <stddev>0.1</stddev>
           </noise>
        </ray>

    </sensor>

    <collision name="top_collision">
      <geometry>
        <cylinder>
          <radius>0.04267</radius>
          <length>0.07357</length>
        </cylinder>
      </geometry>
    </collision>
    <visual name="top_visual">
      <pose>0 0 -0.0376785 0 0 1.5707</pose>
      <geometry>
        <mesh>
            <uri>model://velodyne_hdl-32/meshes/top_t.dae</uri>
        </mesh>
        <!-- 
        <cylinder>
          <radius>0.04267</radius>
          <length>0.07357</length>
        </cylinder>
        -->
      </geometry>
    </visual>
  </link>

  <joint type="revolute" name="joint">
      <pose>0 0 -0.036785 0 0 0</pose>
      <parent>base</parent>
      <child>top</child>
      <axis>
        <xyz>0 0 1</xyz>
    
        <limit>
          <!-- 使用一个很大的数来表示无限转动 -->
          <lower>-10000000000000000</lower>
          <upper>10000000000000000</upper>
        </limit>
      </axis>
    </joint>
    
    <!-- 自定义的plugin -->
    <plugin name="velodyne_control" filename="libvelodyne_plugin.so">
        <velocity>5.0</velocity>
    </plugin>

</model>
</sdf>
