<?xml version="1.0" encoding="utf-8"?>
<robot xmlns:xacro="http://wiki.ros.org/xacro" name="gripper">

    <xacro:include filename="$(find panda_gripper_description)/urdf/gripper.transmission.xacro"/>
    <xacro:include filename="$(find panda_gripper_description)/urdf/gripper.gazebo.xacro"/>

    <xacro:macro name="gripper" params="connected_to:='' rpy:='0 0 0' xyz:='0 0 0'">
        <xacro:unless value="${connected_to == ''}">
            <joint name="gripper_joint" type="fixed">
                <parent link="${connected_to}"/>
                <child link="palm_link"/>
                <origin xyz="${xyz}" rpy="${rpy}"/>
            </joint>
        </xacro:unless>
        <!--x:0.05(0.0025),y:0.15(0.0225),z:0.03(0.0009)-->

        <link name="palm_link">
            <visual>
                <geometry>
                    <mesh filename="package://panda_gripper_description/meshes/visual/hand.dae"/>
                </geometry>
            </visual>
            <collision>
                <geometry>
                    <mesh filename="package://panda_gripper_description/meshes/collision/hand.stl"/>
                </geometry>
            </collision>
            <inertial>
                <mass value="1"/>
                <inertia ixx="0.00195" iyy="0.00028" izz="0.00208" ixy="0.0" ixz="0.0" iyz="0.0"/>
            </inertial>
        </link>

        <!--x:0.05(0.0025),y:0.025(0.000625),z:0.025(0.000625)-->
        <link name="left_finger_link">
            <visual>
                <geometry>
                    <mesh filename="package://panda_gripper_description/meshes/visual/finger.dae"/>
                </geometry>
            </visual>
            <collision>
                <geometry>
                    <mesh filename="package://panda_gripper_description/meshes/collision/finger.stl"/>
                </geometry>
            </collision>
            <inertial>
                <mass value="0.1"/>
                <inertia ixx="0.0000104" iyy="0.000026" izz="0.000026" ixy="0.0" ixz="0.0" iyz="0.0"/>
            </inertial>
        </link>
        <link name="right_finger_link">
            <visual>
                <origin xyz="0 0 0" rpy="0 0 ${pi}"/>
                <geometry>
                    <mesh filename="package://panda_gripper_description/meshes/visual/finger.dae"/>
                </geometry>
            </visual>
            <collision>
                <origin xyz="0 0 0" rpy="0 0 ${pi}"/>
                <geometry>
                    <mesh filename="package://panda_gripper_description/meshes/collision/finger.stl"/>
                </geometry>
            </collision>
            <inertial>
                <mass value="0.1"/>
                <inertia ixx="0.0000104" iyy="0.000026" izz="0.000026" ixy="0.0" ixz="0.0" iyz="0.0"/>
            </inertial>
        </link>
        <joint name="left_finger_joint" type="prismatic">
            <parent link="palm_link"/>
            <child link="left_finger_link"/>
            <origin xyz="0 0 0.0584" rpy="0 0 0"/>
            <axis xyz="0 1 0"/>
            <limit effort="20" lower="0.0" upper="0.04" velocity="0.2"/>
        </joint>
        <joint name="right_finger_joint" type="prismatic">
            <parent link="palm_link"/>
            <child link="right_finger_link"/>
            <origin xyz="0 0 0.0584" rpy="0 0 0"/>
            <axis xyz="0 -1 0"/>
            <limit effort="20" lower="0.0" upper="0.04" velocity="0.2"/>
        </joint>

        <!-- transmission -->
        <xacro:gripper_transmission />
    
        <!-- gazebo -->
        <xacro:gripper_gazebo/>

    </xacro:macro>

    <!-- <xacro:gripper /> -->

</robot>
